Workbook

Sheet Test Specimens
A1: AM IN625 Compression
A2: Sample ID | B2: Height (mm) | C2: Diameter (mm) | D2: AVG. H (mm) | E2: AVG D (mm) | F2: Area (mm^2) | G2: 30% Strain (mm)
A3: V2 | B3: 4.37134 | C3: 2.80162 | D3: =AVERAGE(B3:B5) -> 4.37134 | E3: =AVERAGE(C3:C5) -> 2.8037367 | F3: =PI()/4*(E3)^2 -> 6.1739673 | G3: =D3*0.3 -> 1.311402
B4: 4.37134 | C4: 2.80543
B5: 4.37134 | C5: 2.80416
A6: V3 | B6: 4.37134 | C6: 2.80162 | D6: =AVERAGE(B6:B8) -> 4.37134 | E6: =AVERAGE(C6:C8) -> 2.8020433 | F6: =PI()/4*(E6)^2 -> 6.1665119 | G6: =D6*0.3 -> 1.311402
B7: 4.37134 | C7: 2.80162
B8: 4.37134 | C8: 2.80289
A11: Note: This data was produced from the Inconel 625 NIST AMB2018-01 sample. As such, the results here are only representative of that
A12: particular sample. The results from this dataset should not be in any way used to calibrate models for any such use other than
A13: for use within the NIST CHAL-AMB2022-04-MaCTO problem.

Sheet Summary 
A1: Specimen | B1: Alternative Name | C1: .2% Offset Yield (MPa) | D1: Compressive Strength (MPa) | F1: Compressive Strain (%) | H1: Temperature (°C)
D2: Engineering | E2: TRUE | F2: Engineering | G2: TRUE
A3: V2 | B3: Build Direction 500C #1 | C3: 622 | D3: 1814 | E3: 1274 | F3: 28.3 | G3: 35.3 | H3: 500
A4: V3 | B4: Build Direction RT #1 | C4: 750 | D4: 2147 | E4: 1488 | F4: 33.3 | G4: 35.3 | H4: RT

Sheet V2
A1: Time (sec) | B1: Crosshead (mm) | C1: Load (N) | D1: Ext 1 (mm) | E1: Eng Stress (MPa) | F1: Eng Strain (mm/mm) | G1: Eng Strain (%) | H1: True Stress (MPa) | I1: True Strain (mm/mm) | J1: True Strain (%) | L1: Unloaded Elastic Modulus | N1: Estimated part disp (mm) | O1: Estimated Machine Compliance (mm) | P1: Estimated Eng Strain (mm/mm) | Q1: Estimated Eng Strain (%) | R1: Eng Stress (MPa) | S1: Estimated True Strain (mm / mm) | T1: Estimated True Strain (%)
A2: 0 | B2: 0 | C2: 207.96387 | D2: -0.00071 | E2: 33.684 | F2: -0.00016243 | G2: -0.016243 | H2: 33.689 | I2: -0.00016242 | J2: -0.016242 | L2: {=LINEST(E4600:E4800,F4600:F4800,TRUE)} -> 246157.47 | M2: -72243.387 | N2: =E2*$L$4*'Test Specimens'!$B$4 -> 0.00059817082 | O2: =D2-N2 -> -0.0013081708 | P2: =(D2-O2)/'Test Specimens'!$B$4 -> 0.00013683923 | Q2: =P2*100 -> 0.013683923 | R2: =E2 -> 33.684 | S2: =ABS(LN(1 - P2)) -> 0.0001368486 | T2: =S2 * 100 -> 0.01368486
A3: 0.0018 | B3: 0 | C3: 207.50471 | D3: -0.00072 | E3: 33.609 | F3: -0.00016472 | G3: -0.016472 | H3: 33.615 | I3: -0.00016471 | J3: -0.016471 | L3: Unloaded Elastic Compliance | N3: =E3*$L$4*'Test Specimens'!$B$4 -> 0.00059683894 | O3: =D3-N3 -> -0.0013168389 | P3: =(D3-O3)/'Test Specimens'!$B$4 -> 0.00013653455 | Q3: =P3*100 -> 0.013653455 | R3: =E3 -> 33.609 | S3: =ABS(LN(1 - P3)) -> 0.00013654387 | T3: =S3 * 100 -> 0.013654387
A4: 0.1 | B4: 0.00013 | C4: 212.07497 | D4: -0.00071 | E4: 34.35 | F4: -0.00016243 | G4: -0.016243 | H4: 34.355 | I4: -0.00016242 | J4: -0.016242 | L4: =1/L2 -> 4.0624401e-06 | N4: =E4*$L$4*'Test Specimens'!$B$4 -> 0.00060999785 | O4: =D4-N4 -> -0.0013199978 | P4: =(D4-O4)/'Test Specimens'!$B$4 -> 0.00013954482 | Q4: =P4*100 -> 0.013954482 | R4: =E4 -> 34.35 | S4: =ABS(LN(1 - P4)) -> 0.00013955456 | T4: =S4 * 100 -> 0.013955456
A5: 0.2 | B5: 0.00044 | C5: 214.32689 | D5: -0.00074 | E5: 34.714 | F5: -0.0001693 | G5: -0.01693 | H5: 34.72 | I5: -0.00016928 | J5: -0.016928 | N5: =E5*$L$4*'Test Specimens'!$B$4 -> 0.00061646187 | O5: =D5-N5 -> -0.0013564619 | P5: =(D5-O5)/'Test Specimens'!$B$4 -> 0.00014102355 | Q5: =P5*100 -> 0.014102355 | R5: =E5 -> 34.714 | S5: =ABS(LN(1 - P5)) -> 0.00014103349 | T5: =S5 * 100 -> 0.014103349
A6: 0.3 | B6: 0.00087 | C6: 212.95412 | D6: -0.00067 | E6: 34.492 | F6: -0.00015328 | G6: -0.015328 | H6: 34.497 | I6: -0.00015327 | J6: -0.015327 | L6: =RSQ(E4600:E4800,F4600:F4800) -> 0.99798278 | N6: =E6*$L$4*'Test Specimens'!$B$4 -> 0.00061251953 | O6: =D6-N6 -> -0.0012825195 | P6: =(D6-O6)/'Test Specimens'!$B$4 -> 0.00014012169 | Q6: =P6*100 -> 0.014012169 | R6: =E6 -> 34.492 | S6: =ABS(LN(1 - P6)) -> 0.0001401315 | T6: =S6 * 100 -> 0.01401315
A7: 0.4 | B7: 0.00136 | C7: 216.73109 | D7: -0.00067 | E7: 35.104 | F7: -0.00015328 | G7: -0.015328 | H7: 35.109 | I7: -0.00015327 | J7: -0.015327 | N7: =E7*$L$4*'Test Specimens'!$B$4 -> 0.00062338761 | O7: =D7-N7 -> -0.0012933876 | P7: =(D7-O7)/'Test Specimens'!$B$4 -> 0.0001426079 | Q7: =P7*100 -> 0.01426079 | R7: =E7 -> 35.104 | S7: =ABS(LN(1 - P7)) -> 0.00014261807 | T7: =S7 * 100 -> 0.014261807
A8: 0.5 | B8: 0.00185 | C8: 218.11691 | D8: -0.00065 | E8: 35.328 | F8: -0.00014871 | G8: -0.014871 | H8: 35.334 | I8: -0.0001487 | J8: -0.01487 | N8: =E8*$L$4*'Test Specimens'!$B$4 -> 0.00062736547 | O8: =D8-N8 -> -0.0012773655 | P8: =(D8-O8)/'Test Specimens'!$B$4 -> 0.00014351789 | Q8: =P8*100 -> 0.014351789 | R8: =E8 -> 35.328 | S8: =ABS(LN(1 - P8)) -> 0.00014352818 | T8: =S8 * 100 -> 0.014352818
A9: 0.6 | B9: 0.00232 | C9: 224.32744 | D9: -0.00054 | E9: 36.334 | F9: -0.00012354 | G9: -0.012354 | H9: 36.339 | I9: -0.00012353 | J9: -0.012353 | N9: =E9*$L$4*'Test Specimens'!$B$4 -> 0.00064523033 | O9: =D9-N9 -> -0.0011852303 | P9: =(D9-O9)/'Test Specimens'!$B$4 -> 0.0001476047 | Q9: =P9*100 -> 0.01476047 | R9: =E9 -> 36.334 | S9: =ABS(LN(1 - P9)) -> 0.00014761559 | T9: =S9 * 100 -> 0.014761559
A10: 0.7 | B10: 0.00277 | C10: 227.31837 | D10: -0.00089 | E10: 36.819 | F10: -0.00020361 | G10: -0.020361 | H10: 36.826 | I10: -0.00020359 | J10: -0.020359 | L10: {=LINEST(O5:O520,C5:C520,TRUE)} -> 7.0722081e-06 | M10: -0.0012242687 | N10: =E10*$L$4*'Test Specimens'!$B$4 -> 0.00065384311 | O10: =D10-N10 -> -0.0015438431 | P10: =(D10-O10)/'Test Specimens'!$B$4 -> 0.00014957498 | Q10: =P10*100 -> 0.014957498 | R10: =E10 -> 36.819 | S10: =ABS(LN(1 - P10)) -> 0.00014958617 | T10: =S10 * 100 -> 0.014958617
A11: 0.8 | B11: 0.00321 | C11: 231.24367 | D11: -0.00055 | E11: 37.454 | F11: -0.00012583 | G11: -0.012583 | H11: 37.459 | I11: -0.00012582 | J11: -0.012582 | L11: =RSQ(O450:O520,C450:C520) -> 0.99171681 | N11: =E11*$L$4*'Test Specimens'!$B$4 -> 0.00066511963 | O11: =D11-N11 -> -0.0012151196 | P11: =(D11-O11)/'Test Specimens'!$B$4 -> 0.00015215463 | Q11: =P11*100 -> 0.015215463 | R11: =E11 -> 37.454 | S11: =ABS(LN(1 - P11)) -> 0.00015216621 | T11: =S11 * 100 -> 0.015216621
A12: 0.9 | B12: 0.00366 | C12: 236.30867 | D12: -0.00057 | E12: 38.275 | F12: -0.0001304 | G12: -0.01304 | H12: 38.28 | I12: -0.0001304 | J12: -0.01304 | N12: =E12*$L$4*'Test Specimens'!$B$4 -> 0.0006796992 | O12: =D12-N12 -> -0.0012496992 | P12: =(D12-O12)/'Test Specimens'!$B$4 -> 0.0001554899 | Q12: =P12*100 -> 0.01554899 | R12: =E12 -> 38.275 | S12: =ABS(LN(1 - P12)) -> 0.00015550199 | T12: =S12 * 100 -> 0.015550199
A13: 1 | B13: 0.00408 | C13: 238.6407 | D13: -0.00054 | E13: 38.653 | F13: -0.00012354 | G13: -0.012354 | H13: 38.657 | I13: -0.00012353 | J13: -0.012353 | N13: =E13*$L$4*'Test Specimens'!$B$4 -> 0.00068641184 | O13: =D13-N13 -> -0.0012264118 | P13: =(D13-O13)/'Test Specimens'!$B$4 -> 0.0001570255 | Q13: =P13*100 -> 0.01570255 | R13: =E13 -> 38.653 | S13: =ABS(LN(1 - P13)) -> 0.00015703783 | T13: =S13 * 100 -> 0.015703783
A14: 1.1 | B14: 0.00448 | C14: 242.89474 | D14: -0.0005 | E14: 39.342 | F14: -0.00011439 | G14: -0.011439 | H14: 39.346 | I14: -0.00011438 | J14: -0.011438 | N14: =E14*$L$4*'Test Specimens'!$B$4 -> 0.00069864732 | O14: =D14-N14 -> -0.0011986473 | P14: =(D14-O14)/'Test Specimens'!$B$4 -> 0.00015982452 | Q14: =P14*100 -> 0.015982452 | R14: =E14 -> 39.342 | S14: =ABS(LN(1 - P14)) -> 0.00015983729 | T14: =S14 * 100 -> 0.015983729
A15: 1.2 | B15: 0.0049 | C15: 250.27805 | D15: -0.00043 | E15: 40.537 | F15: -9.8376e-05 | G15: -0.0098376 | H15: 40.541 | I15: -9.8371e-05 | J15: -0.0098371 | L15: {=LINEST(E4613:E4813,P4613:P4813,TRUE)} -> 245683.03 | M15: -67770.751 | N15: =E15*$L$4*'Test Specimens'!$B$4 -> 0.00071986849 | O15: =D15-N15 -> -0.0011498685 | P15: =(D15-O15)/'Test Specimens'!$B$4 -> 0.00016467914 | Q15: =P15*100 -> 0.016467914 | R15: =E15 -> 40.537 | S15: =ABS(LN(1 - P15)) -> 0.0001646927 | T15: =S15 * 100 -> 0.01646927
A16: 1.3 | B16: 0.00534 | C16: 253.08691 | D16: -0.00038 | E16: 40.992 | F16: -8.6937e-05 | G16: -0.0086937 | H16: 40.996 | I16: -8.6933e-05 | J16: -0.0086933 | N16: =E16*$L$4*'Test Specimens'!$B$4 -> 0.00072794852 | O16: =D16-N16 -> -0.0011079485 | P16: =(D16-O16)/'Test Specimens'!$B$4 -> 0.00016652755 | Q16: =P16*100 -> 0.016652755 | R16: =E16 -> 40.992 | S16: =ABS(LN(1 - P16)) -> 0.00016654141 | T16: =S16 * 100 -> 0.016654141
A17: 1.4 | B17: 0.00579 | C17: 263.71866 | D17: -0.00023 | E17: 42.714 | F17: -5.262e-05 | G17: -0.005262 | H17: 42.717 | I17: -5.2618e-05 | J17: -0.0052618 | N17: =E17*$L$4*'Test Specimens'!$B$4 -> 0.00075852833 | O17: =D17-N17 -> -0.00098852833 | P17: =(D17-O17)/'Test Specimens'!$B$4 -> 0.00017352307 | Q17: =P17*100 -> 0.017352307 | R17: =E17 -> 42.714 | S17: =ABS(LN(1 - P17)) -> 0.00017353812 | T17: =S17 * 100 -> 0.017353812
A18: 1.5 | B18: 0.00622 | C18: 268.34778 | D18: -0.00033 | E18: 43.464 | F18: -7.5498e-05 | G18: -0.0075498 | H18: 43.467 | I18: -7.5495e-05 | J18: -0.0075495 | N18: =E18*$L$4*'Test Specimens'!$B$4 -> 0.00077184706 | O18: =D18-N18 -> -0.0011018471 | P18: =(D18-O18)/'Test Specimens'!$B$4 -> 0.0001765699 | Q18: =P18*100 -> 0.01765699 | R18: =E18 -> 43.464 | S18: =ABS(LN(1 - P18)) -> 0.00017658549 | T18: =S18 * 100 -> 0.017658549
A19: 1.6 | B19: 0.00667 | C19: 270.73337 | D19: -0.00025 | E19: 43.851 | F19: -5.7195e-05 | G19: -0.0057195 | H19: 43.853 | I19: -5.7194e-05 | J19: -0.0057194 | N19: =E19*$L$4*'Test Specimens'!$B$4 -> 0.00077871952 | O19: =D19-N19 -> -0.0010287195 | P19: =(D19-O19)/'Test Specimens'!$B$4 -> 0.00017814206 | Q19: =P19*100 -> 0.017814206 | R19: =E19 -> 43.851 | S19: =ABS(LN(1 - P19)) -> 0.00017815793 | T19: =S19 * 100 -> 0.017815793
A20: 1.7 | B20: 0.00708 | C20: 277.36346 | D20: -0.00018 | E20: 44.924 | F20: -4.1181e-05 | G20: -0.0041181 | H20: 44.926 | I20: -4.118e-05 | J20: -0.004118 | N20: =E20*$L$4*'Test Specimens'!$B$4 -> 0.00079777419 | O20: =D20-N20 -> -0.00097777419 | P20: =(D20-O20)/'Test Specimens'!$B$4 -> 0.00018250106 | Q20: =P20*100 -> 0.018250106 | R20: =E20 -> 44.924 | S20: =ABS(LN(1 - P20)) -> 0.00018251772 | T20: =S20 * 100 -> 0.018251772
A21: 1.8 | B21: 0.00752 | C21: 285.13394 | D21: -6e-05 | E21: 46.183 | F21: -1.3727e-05 | G21: -0.0013727 | H21: 46.184 | I21: -1.3727e-05 | J21: -0.0013727 | N21: =E21*$L$4*'Test Specimens'!$B$4 -> 0.0008201319 | O21: =D21-N21 -> -0.0008801319 | P21: =(D21-O21)/'Test Specimens'!$B$4 -> 0.00018761567 | Q21: =P21*100 -> 0.018761567 | R21: =E21 -> 46.183 | S21: =ABS(LN(1 - P21)) -> 0.00018763327 | T21: =S21 * 100 -> 0.018763327
A22: 1.9 | B22: 0.00794 | C22: 293.25998 | D22: 3e-05 | E22: 47.499 | F22: 6.8633e-06 | G22: 0.00068633 | H22: 47.499 | I22: 6.8634e-06 | J22: 0.00068634 | N22: =E22*$L$4*'Test Specimens'!$B$4 -> 0.00084350183 | O22: =D22-N22 -> -0.00081350183 | P22: =(D22-O22)/'Test Specimens'!$B$4 -> 0.00019296184 | Q22: =P22*100 -> 0.019296184 | R22: =E22 -> 47.499 | S22: =ABS(LN(1 - P22)) -> 0.00019298046 | T22: =S22 * 100 -> 0.019298046
A23: 2 | B23: 0.00838 | C23: 297.70145 | D23: 1e-05 | E23: 48.219 | F23: 2.2877e-06 | G23: 0.00022877 | H23: 48.218 | I23: 2.2877e-06 | J23: 0.00022877 | N23: =E23*$L$4*'Test Specimens'!$B$4 -> 0.00085628781 | O23: =D23-N23 -> -0.00084628781 | P23: =(D23-O23)/'Test Specimens'!$B$4 -> 0.0001958868 | Q23: =P23*100 -> 0.01958868 | R23: =E23 -> 48.219 | S23: =ABS(LN(1 - P23)) -> 0.00019590599 | T23: =S23 * 100 -> 0.019590599
A24: 2.1 | B24: 0.00881 | C24: 303.80093 | D24: -8e-05 | E24: 49.207 | F24: -1.8303e-05 | G24: -0.0018303 | H24: 49.207 | I24: -1.8302e-05 | J24: -0.0018302 | N24: =E24*$L$4*'Test Specimens'!$B$4 -> 0.00087383302 | O24: =D24-N24 -> -0.00095383302 | P24: =(D24-O24)/'Test Specimens'!$B$4 -> 0.00019990049 | Q24: =P24*100 -> 0.019990049 | R24: =E24 -> 49.207 | S24: =ABS(LN(1 - P24)) -> 0.00019992047 | T24: =S24 * 100 -> 0.019992047
A25: 2.2 | B25: 0.00921 | C25: 310.21307 | D25: 0.00019 | E25: 50.245 | F25: 4.3468e-05 | G25: 0.0043468 | H25: 50.243 | I25: 4.3469e-05 | J25: 0.0043469 | N25: =E25*$L$4*'Test Specimens'!$B$4 -> 0.00089226614 | O25: =D25-N25 -> -0.00070226614 | P25: =(D25-O25)/'Test Specimens'!$B$4 -> 0.0002041173 | Q25: =P25*100 -> 0.02041173 | R25: =E25 -> 50.245 | S25: =ABS(LN(1 - P25)) -> 0.00020413814 | T25: =S25 * 100 -> 0.020413814
A26: 2.3 | B26: 0.00963 | C26: 317.23944 | D26: 0.00038 | E26: 51.383 | F26: 8.6936e-05 | G26: 0.0086936 | H26: 51.379 | I26: 8.694e-05 | J26: 0.008694 | N26: =E26*$L$4*'Test Specimens'!$B$4 -> 0.00091247509 | O26: =D26-N26 -> -0.00053247509 | P26: =(D26-O26)/'Test Specimens'!$B$4 -> 0.00020874036 | Q26: =P26*100 -> 0.020874036 | R26: =E26 -> 51.383 | S26: =ABS(LN(1 - P26)) -> 0.00020876215 | T26: =S26 * 100 -> 0.020876215
A27: 2.4 | B27: 0.01003 | C27: 322.36057 | D27: 0.00036 | E27: 52.213 | F27: 8.2361e-05 | G27: 0.0082361 | H27: 52.208 | I27: 8.2364e-05 | J27: 0.0082364 | N27: =E27*$L$4*'Test Specimens'!$B$4 -> 0.00092721449 | O27: =D27-N27 -> -0.00056721449 | P27: =(D27-O27)/'Test Specimens'!$B$4 -> 0.00021211219 | Q27: =P27*100 -> 0.021211219 | R27: =E27 -> 52.213 | S27: =ABS(LN(1 - P27)) -> 0.00021213469 | T27: =S27 * 100 -> 0.021213469
... A520: 51.7 | B520: 0.21882 | C520: 3452.8132 | D520: 0.03319 | E520: 559.25 | F520: 0.0075932 | G520: 0.75932 | H520: 555 | I520: 0.0076222 | J520: 0.76222 | N520: =E520*$L$4*'Test Specimens'!$B$4 -> 0.0099313332 | O520: =D520-N520 -> 0.023258667 | P520: =(D520-O520)/'Test Specimens'!$B$4 -> 0.0022719196 | Q520: =P520*100 -> 0.22719196 | R520: =E520 -> 559.25 | S520: =ABS(LN(1 - P520)) -> 0.0022745044 | T520: =S520 * 100 -> 0.22745044
A521: 51.8 | B521: 0.21924 | C521: 3461.3765 | D521: 0.03334 | E521: 560.64 | F521: 0.0076275 | G521: 0.76275 | H521: 556.36 | I521: 0.0076568 | J521: 0.76568 | N521: =E521*$L$4*'Test Specimens'!$B$4 -> 0.0099560173 | O521: =C521*$L$10+$M$10 -> 0.023255306 | P521: =(D521-O521)/'Test Specimens'!$B$4 -> 0.0023070029 | Q521: =P521*100 -> 0.23070029 | R521: =E521 -> 560.64 | S521: =ABS(LN(1 - P521)) -> 0.0023096682 | T521: =S521 * 100 -> 0.23096682
A522: 51.9 | B522: 0.21963 | C522: 3463.3662 | D522: 0.0334 | E522: 560.96 | F522: 0.0076413 | G522: 0.76413 | H522: 556.67 | I522: 0.0076706 | J522: 0.76706 | N522: =E522*$L$4*'Test Specimens'!$B$4 -> 0.0099616999 | O522: =C522*$L$10+$M$10 -> 0.023269378 | P522: =(D522-O522)/'Test Specimens'!$B$4 -> 0.0023175096 | Q522: =P522*100 -> 0.23175096 | R522: =E522 -> 560.96 | S522: =ABS(LN(1 - P522)) -> 0.0023201991 | T522: =S522 * 100 -> 0.23201991
A523: 52 | B523: 0.22005 | C523: 3470.729 | D523: 0.03336 | E523: 562.15 | F523: 0.0076321 | G523: 0.76321 | H523: 557.86 | I523: 0.0076614 | J523: 0.76614 | N523: =E523*$L$4*'Test Specimens'!$B$4 -> 0.0099828323 | O523: =C523*$L$10+$M$10 -> 0.023321449 | P523: =(D523-O523)/'Test Specimens'!$B$4 -> 0.0022964471 | Q523: =P523*100 -> 0.22964471 | R523: =E523 -> 562.15 | S523: =ABS(LN(1 - P523)) -> 0.002299088 | T523: =S523 * 100 -> 0.2299088
A524: 52.1 | B524: 0.22048 | C524: 3477.1853 | D524: 0.03354 | E524: 563.2 | F524: 0.0076733 | G524: 0.76733 | H524: 558.88 | I524: 0.0077029 | J524: 0.77029 | N524: =E524*$L$4*'Test Specimens'!$B$4 -> 0.010001479 | O524: =C524*$L$10+$M$10 -> 0.023367109 | P524: =(D524-O524)/'Test Specimens'!$B$4 -> 0.002327179 | Q524: =P524*100 -> 0.2327179 | R524: =E524 -> 563.2 | S524: =ABS(LN(1 - P524)) -> 0.0023298911 | T524: =S524 * 100 -> 0.23298911
A525: 52.2 | B525: 0.2209 | C525: 3485.8347 | D525: 0.03374 | E525: 564.6 | F525: 0.007719 | G525: 0.7719 | H525: 560.24 | I525: 0.007749 | J525: 0.7749 | N525: =E525*$L$4*'Test Specimens'!$B$4 -> 0.01002634 | O525: =C525*$L$10+$M$10 -> 0.02342828 | P525: =(D525-O525)/'Test Specimens'!$B$4 -> 0.0023589381 | Q525: =P525*100 -> 0.23589381 | R525: =E525 -> 564.6 | S525: =ABS(LN(1 - P525)) -> 0.0023617247 | T525: =S525 * 100 -> 0.23617247
A526: 52.3 | B526: 0.22131 | C526: 3491.0391 | D526: 0.03356 | E526: 565.44 | F526: 0.0076779 | G526: 0.76779 | H526: 561.1 | I526: 0.0077075 | J526: 0.77075 | N526: =E526*$L$4*'Test Specimens'!$B$4 -> 0.010041257 | O526: =C526*$L$10+$M$10 -> 0.023465086 | P526: =(D526-O526)/'Test Specimens'!$B$4 -> 0.0023093409 | Q526: =P526*100 -> 0.23093409 | R526: =E526 -> 565.44 | S526: =ABS(LN(1 - P526)) -> 0.0023120115 | T526: =S526 * 100 -> 0.23120115
A527: 52.4 | B527: 0.22172 | C527: 3499.116 | D527: 0.03371 | E527: 566.75 | F527: 0.0077122 | G527: 0.77122 | H527: 562.38 | I527: 0.0077421 | J527: 0.77421 | N527: =E527*$L$4*'Test Specimens'!$B$4 -> 0.010064521 | O527: =C527*$L$10+$M$10 -> 0.023522207 | P527: =(D527-O527)/'Test Specimens'!$B$4 -> 0.002330588 | Q527: =P527*100 -> 0.2330588 | R527: =E527 -> 566.75 | S527: =ABS(LN(1 - P527)) -> 0.002333308 | T527: =S527 * 100 -> 0.2333308
A528: 52.5 | B528: 0.22214 | C528: 3502.0352 | D528: 0.03382 | E528: 567.22 | F528: 0.0077373 | G528: 0.77373 | H528: 562.83 | I528: 0.0077674 | J528: 0.77674 | N528: =E528*$L$4*'Test Specimens'!$B$4 -> 0.010072867 | O528: =C528*$L$10+$M$10 -> 0.023542853 | P528: =(D528-O528)/'Test Specimens'!$B$4 -> 0.0023510291 | Q528: =P528*100 -> 0.23510291 | R528: =E528 -> 567.22 | S528: =ABS(LN(1 - P528)) -> 0.0023537971 | T528: =S528 * 100 -> 0.23537971
A529: 52.6 | B529: 0.22258 | C529: 3510.3215 | D529: 0.03397 | E529: 568.57 | F529: 0.0077717 | G529: 0.77717 | H529: 564.15 | I529: 0.007802 | J529: 0.7802 | N529: =E529*$L$4*'Test Specimens'!$B$4 -> 0.010096841 | O529: =C529*$L$10+$M$10 -> 0.023601456 | P529: =(D529-O529)/'Test Specimens'!$B$4 -> 0.0023719373 | Q529: =P529*100 -> 0.23719373 | R529: =E529 -> 568.57 | S529: =ABS(LN(1 - P529)) -> 0.0023747548 | T529: =S529 * 100 -> 0.23747548
A530: 52.7 | B530: 0.22302 | C530: 3515.406 | D530: 0.03401 | E530: 569.39 | F530: 0.0077808 | G530: 0.77808 | H530: 564.96 | I530: 0.0078112 | J530: 0.78112 | N530: =E530*$L$4*'Test Specimens'!$B$4 -> 0.010111402 | O530: =C530*$L$10+$M$10 -> 0.023637414 | P530: =(D530-O530)/'Test Specimens'!$B$4 -> 0.0023728619 | Q530: =P530*100 -> 0.23728619 | R530: =E530 -> 569.39 | S530: =ABS(LN(1 - P530)) -> 0.0023756816 | T530: =S530 * 100 -> 0.23756816
A531: 52.8 | B531: 0.22344 | C531: 3523.5344 | D531: 0.03421 | E531: 570.71 | F531: 0.0078266 | G531: 0.78266 | H531: 566.24 | I531: 0.0078574 | J531: 0.78574 | N531: =E531*$L$4*'Test Specimens'!$B$4 -> 0.010134843 | O531: =C531*$L$10+$M$10 -> 0.0236949 | P531: =(D531-O531)/'Test Specimens'!$B$4 -> 0.0024054638 | Q531: =P531*100 -> 0.24054638 | R531: =E531 -> 570.71 | S531: =ABS(LN(1 - P531)) -> 0.0024083616 | T531: =S531 * 100 -> 0.24083616
A532: 52.9 | B532: 0.22385 | C532: 3527.7488 | D532: 0.03419 | E532: 571.39 | F532: 0.007822 | G532: 0.7822 | H532: 566.92 | I532: 0.0078527 | J532: 0.78527 | N532: =E532*$L$4*'Test Specimens'!$B$4 -> 0.010146919 | O532: =C532*$L$10+$M$10 -> 0.023724705 | P532: =(D532-O532)/'Test Specimens'!$B$4 -> 0.0023940703 | Q532: =P532*100 -> 0.23940703 | R532: =E532 -> 571.39 | S532: =ABS(LN(1 - P532)) -> 0.0023969407 | T532: =S532 * 100 -> 0.23969407
...

Sheet V3
A1: Time (sec) | B1: Crosshead (mm) | C1: Load (N) | D1: Ext 1 (mm) | E1: Eng Stress (MPa) | F1: Eng Strain (mm/mm) | G1: Eng Strain (%) | H1: True Stress (MPa) | I1: True Strain (mm/mm) | J1: True Strain (%) | L1: Unloaded Elastic Modulus | N1: Estimated part disp (mm) | O1: Estimated Machine Compliance (mm) | P1: Estimated Eng Strain (mm/mm) | Q1: Estimated Eng Strain (%) | R1: Eng Stress (MPa) | S1: Estimated True Strain (mm / mm) | T1: Estimated True Strain (%)
A2: 0 | B2: 0 | C2: 219.59096 | D2: 0.00193 | E2: 35.61897 | F2: 0.00044155 | G2: 0.044155 | H2: 35.603 | I2: 0.00044164 | J2: 0.044164 | L2: {=LINEST(E3184:E3250,F3184:F3250,TRUE)} -> 212883.51 | M2: -63478.061 | N2: =E2*$L$4*'Test Specimens'!$B$7 -> 0.00073139825 | O2: =D2-N2 -> 0.0011986017 | P2: =(D2-O2)/'Test Specimens'!$B$7 -> 0.00016731672 | Q2: =P2*100 -> 0.016731672 | R2: 35.61897 | S2: =ABS(LN(1 - P2)) -> 0.00016733071 | T2: =S2 * 100 -> 0.016733071
A3: 0.0018 | B3: 0 | C3: 219.62518 | D3: 0.00193 | E3: 35.62452 | F3: 0.00044155 | G3: 0.044155 | H3: 35.609 | I3: 0.00044164 | J3: 0.044164 | L3: Unloaded Elastic Compliance | N3: =E3*$L$4*'Test Specimens'!$B$7 -> 0.00073151222 | O3: =D3-N3 -> 0.0011984878 | P3: =(D3-O3)/'Test Specimens'!$B$7 -> 0.00016734279 | Q3: =P3*100 -> 0.016734279 | R3: 35.62452 | S3: =ABS(LN(1 - P3)) -> 0.00016735679 | T3: =S3 * 100 -> 0.016735679
A4: 0.1 | B4: 1e-05 | C4: 224.39986 | D4: 0.00192 | E4: 36.399 | F4: 0.00043926 | G4: 0.043926 | H4: 36.383 | I4: 0.00043936 | J4: 0.043936 | L4: =1/L2 -> 4.6974047e-06 | N4: =E4*$L$4*'Test Specimens'!$B$7 -> 0.00074741535 | O4: =D4-N4 -> 0.0011725846 | P4: =(D4-O4)/'Test Specimens'!$B$7 -> 0.00017098083 | Q4: =P4*100 -> 0.017098083 | R4: 36.399 | S4: =ABS(LN(1 - P4)) -> 0.00017099545 | T4: =S4 * 100 -> 0.017099545
A5: 0.2 | B5: 0.00036 | C5: 222.88039 | D5: 0.00186 | E5: 36.15253 | F5: 0.00042553 | G5: 0.042553 | H5: 36.137 | I5: 0.00042562 | J5: 0.042562 | N5: =E5*$L$4*'Test Specimens'!$B$7 -> 0.00074235435 | O5: =D5-N5 -> 0.0011176457 | P5: =(D5-O5)/'Test Specimens'!$B$7 -> 0.00016982306 | Q5: =P5*100 -> 0.016982306 | R5: 36.15253 | S5: =ABS(LN(1 - P5)) -> 0.00016983748 | T5: =S5 * 100 -> 0.016983748
A6: 0.3 | B6: 0.00102 | C6: 234.58688 | D6: 0.00193 | E6: 38.0514 | F6: 0.00044155 | G6: 0.044155 | H6: 38.035 | I6: 0.00044164 | J6: 0.044164 | L6: =RSQ(E3184:E3250,F3184:F3250) -> 0.99602225 | N6: =E6*$L$4*'Test Specimens'!$B$7 -> 0.00078134566 | O6: =D6-N6 -> 0.0011486543 | P6: =(D6-O6)/'Test Specimens'!$B$7 -> 0.00017874282 | Q6: =P6*100 -> 0.017874282 | R6: 38.0514 | S6: =ABS(LN(1 - P6)) -> 0.0001787588 | T6: =S6 * 100 -> 0.01787588
A7: 0.4 | B7: 0.00218 | C7: 253.93721 | D7: 0.00209 | E7: 41.19014 | F7: 0.00047815 | G7: 0.047815 | H7: 41.17 | I7: 0.00047827 | J7: 0.047827 | N7: =E7*$L$4*'Test Specimens'!$B$7 -> 0.00084579639 | O7: =D7-N7 -> 0.0012442036 | P7: =(D7-O7)/'Test Specimens'!$B$7 -> 0.00019348676 | Q7: =P7*100 -> 0.019348676 | R7: 41.19014 | S7: =ABS(LN(1 - P7)) -> 0.00019350548 | T7: =S7 * 100 -> 0.019350548
A8: 0.5 | B8: 0.00369 | C8: 278.1041 | D8: 0.00215 | E8: 45.11015 | F8: 0.00049188 | G8: 0.049188 | H8: 45.088 | I8: 0.000492 | J8: 0.0492 | N8: =E8*$L$4*'Test Specimens'!$B$7 -> 0.0009262897 | O8: =D8-N8 -> 0.0012237103 | P8: =(D8-O8)/'Test Specimens'!$B$7 -> 0.00021190063 | Q8: =P8*100 -> 0.021190063 | R8: 45.11015 | S8: =ABS(LN(1 - P8)) -> 0.00021192308 | T8: =S8 * 100 -> 0.021192308
A9: 0.6 | B9: 0.00579 | C9: 317.48648 | D9: 0.00258 | E9: 51.49821 | F9: 0.00059025 | G9: 0.059025 | H9: 51.468 | I9: 0.00059043 | J9: 0.059043 | N9: =E9*$L$4*'Test Specimens'!$B$7 -> 0.0010574618 | O9: =D9-N9 -> 0.0015225382 | P9: =(D9-O9)/'Test Specimens'!$B$7 -> 0.00024190793 | Q9: =P9*100 -> 0.024190793 | R9: 51.49821 | S9: =ABS(LN(1 - P9)) -> 0.0002419372 | T9: =S9 * 100 -> 0.02419372
A10: 0.7 | B10: 0.00816 | C10: 361.63651 | D10: 0.00275 | E10: 58.65961 | F10: 0.00062915 | G10: 0.062915 | H10: 58.623 | I10: 0.00062935 | J10: 0.062935 | L10: {=LINEST(O30:O62,C30:C62,TRUE)} -> 3.4009406e-06 | M10: 0.0011047469 | N10: =E10*$L$4*'Test Specimens'!$B$7 -> 0.0012045137 | O10: =D10-N10 -> 0.0015454863 | P10: =(D10-O10)/'Test Specimens'!$B$7 -> 0.00027554793 | Q10: =P10*100 -> 0.027554793 | R10: 58.65961 | S10: =ABS(LN(1 - P10)) -> 0.0002755859 | T10: =S10 * 100 -> 0.02755859
A11: 0.8 | B11: 0.01083 | C11: 408.14908 | D11: 0.00338 | E11: 66.20423 | F11: 0.00077328 | G11: 0.077328 | H11: 66.153 | I11: 0.00077358 | J11: 0.077358 | L11: =RSQ(O30:O62,C30:C62) -> 0.9974581 | N11: =E11*$L$4*'Test Specimens'!$B$7 -> 0.0013594345 | O11: =D11-N11 -> 0.0020205655 | P11: =(D11-O11)/'Test Specimens'!$B$7 -> 0.00031098806 | Q11: =P11*100 -> 0.031098806 | R11: 66.20423 | S11: =ABS(LN(1 - P11)) -> 0.00031103643 | T11: =S11 * 100 -> 0.031103643
A12: 0.9 | B12: 0.01386 | C12: 467.17795 | D12: 0.00332 | E12: 75.77907 | F12: 0.00075955 | G12: 0.075955 | H12: 75.722 | I12: 0.00075984 | J12: 0.075984 | N12: =E12*$L$4*'Test Specimens'!$B$7 -> 0.0015560439 | O12: =D12-N12 -> 0.0017639561 | P12: =(D12-O12)/'Test Specimens'!$B$7 -> 0.00035596496 | Q12: =P12*100 -> 0.035596496 | R12: 75.77907 | S12: =ABS(LN(1 - P12)) -> 0.00035602833 | T12: =S12 * 100 -> 0.035602833
A13: 1 | B13: 0.01739 | C13: 535.09235 | D13: 0.00373 | E13: 86.79519 | F13: 0.00085335 | G13: 0.085335 | H13: 86.721 | I13: 0.00085372 | J13: 0.085372 | N13: =E13*$L$4*'Test Specimens'!$B$7 -> 0.0017822483 | O13: =D13-N13 -> 0.0019477517 | P13: =(D13-O13)/'Test Specimens'!$B$7 -> 0.00040771213 | Q13: =P13*100 -> 0.040771213 | R13: 86.79519 | S13: =ABS(LN(1 - P13)) -> 0.00040779527 | T13: =S13 * 100 -> 0.040779527
A14: 1.1 | B14: 0.02113 | C14: 602.87842 | D14: 0.00452 | E14: 97.7905 | F14: 0.0010341 | G14: 0.10341 | H14: 97.689 | I14: 0.0010346 | J14: 0.10346 | L14: {=LINEST(E3184:E3250,P3184:P3250,TRUE)} -> 212872.3 | M14: -61223.654 | N14: =E14*$L$4*'Test Specimens'!$B$7 -> 0.0020080255 | O14: =D14-N14 -> 0.0025119745 | P14: =(D14-O14)/'Test Specimens'!$B$7 -> 0.00045936155 | Q14: =P14*100 -> 0.045936155 | R14: 97.7905 | S14: =ABS(LN(1 - P14)) -> 0.00045946709 | T14: =S14 * 100 -> 0.045946709
A15: 1.2 | B15: 0.02486 | C15: 669.11151 | D15: 0.00496 | E15: 108.53391 | F15: 0.0011348 | G15: 0.11348 | H15: 108.41 | I15: 0.0011354 | J15: 0.11354 | N15: =E15*$L$4*'Test Specimens'!$B$7 -> 0.0022286302 | O15: =D15-N15 -> 0.0027313698 | P15: =(D15-O15)/'Test Specimens'!$B$7 -> 0.0005098277 | Q15: =P15*100 -> 0.05098277 | R15: 108.53391 | S15: =ABS(LN(1 - P15)) -> 0.0005099577 | T15: =S15 * 100 -> 0.05099577
A16: 1.3 | B16: 0.02871 | C16: 738.71527 | D16: 0.00542 | E16: 119.82405 | F16: 0.00124 | G16: 0.124 | H16: 119.68 | I16: 0.0012408 | J16: 0.12408 | N16: =E16*$L$4*'Test Specimens'!$B$7 -> 0.0024604614 | O16: =D16-N16 -> 0.0029595386 | P16: =(D16-O16)/'Test Specimens'!$B$7 -> 0.00056286205 | Q16: =P16*100 -> 0.056286205 | R16: 119.82405 | S16: =ABS(LN(1 - P16)) -> 0.00056302052 | T16: =S16 * 100 -> 0.056302052
A17: 1.4 | B17: 0.0328 | C17: 814.51703 | D17: 0.00597 | E17: 132.11955 | F17: 0.0013658 | G17: 0.13658 | H17: 131.94 | I17: 0.0013668 | J17: 0.13668 | N17: =E17*$L$4*'Test Specimens'!$B$7 -> 0.0027129366 | O17: =D17-N17 -> 0.0032570634 | P17: =(D17-O17)/'Test Specimens'!$B$7 -> 0.00062061899 | Q17: =P17*100 -> 0.062061899 | R17: 132.11955 | S17: =ABS(LN(1 - P17)) -> 0.00062081165 | T17: =S17 * 100 -> 0.062081165
A18: 1.5 | B18: 0.03674 | C18: 885.5816 | D18: 0.00656 | E18: 143.64665 | F18: 0.0015008 | G18: 0.15008 | H18: 143.43 | I18: 0.0015019 | J18: 0.15019 | N18: =E18*$L$4*'Test Specimens'!$B$7 -> 0.0029496335 | O18: =D18-N18 -> 0.0036103665 | P18: =(D18-O18)/'Test Specimens'!$B$7 -> 0.00067476644 | Q18: =P18*100 -> 0.067476644 | R18: 143.64665 | S18: =ABS(LN(1 - P18)) -> 0.0006749942 | T18: =S18 * 100 -> 0.06749942
A19: 1.6 | B19: 0.04084 | C19: 962.67834 | D19: 0.00707 | E19: 156.15221 | F19: 0.0016175 | G19: 0.16175 | H19: 155.9 | I19: 0.0016188 | J19: 0.16188 | N19: =E19*$L$4*'Test Specimens'!$B$7 -> 0.0032064221 | O19: =D19-N19 -> 0.0038635779 | P19: =(D19-O19)/'Test Specimens'!$B$7 -> 0.00073351012 | Q19: =P19*100 -> 0.073351012 | R19: 156.15221 | S19: =ABS(LN(1 - P19)) -> 0.00073377927 | T19: =S19 * 100 -> 0.073377927
A20: 1.7 | B20: 0.04488 | C20: 1041.4645 | D20: 0.00768 | E20: 168.93179 | F20: 0.001757 | G20: 0.1757 | H20: 168.63 | I20: 0.0017586 | J20: 0.17586 | N20: =E20*$L$4*'Test Specimens'!$B$7 -> 0.0034688374 | O20: =D20-N20 -> 0.0042111626 | P20: =(D20-O20)/'Test Specimens'!$B$7 -> 0.00079354098 | Q20: =P20*100 -> 0.079354098 | R20: 168.93179 | S20: =ABS(LN(1 - P20)) -> 0.000793856 | T20: =S20 * 100 -> 0.0793856
A21: 1.8 | B21: 0.0488 | C21: 1116.7091 | D21: 0.00841 | E21: 181.13692 | F21: 0.001924 | G21: 0.1924 | H21: 180.79 | I21: 0.0019259 | J21: 0.19259 | N21: =E21*$L$4*'Test Specimens'!$B$7 -> 0.003719457 | O21: =D21-N21 -> 0.004690543 | P21: =(D21-O21)/'Test Specimens'!$B$7 -> 0.00085087341 | Q21: =P21*100 -> 0.085087341 | R21: 181.13692 | S21: =ABS(LN(1 - P21)) -> 0.00085123561 | T21: =S21 * 100 -> 0.085123561
A22: 1.9 | B22: 0.05264 | C22: 1190.9467 | D22: 0.00888 | E22: 193.1787 | F22: 0.0020316 | G22: 0.20316 | H22: 192.79 | I22: 0.0020336 | J22: 0.20336 | N22: =E22*$L$4*'Test Specimens'!$B$7 -> 0.0039667223 | O22: =D22-N22 -> 0.0049132777 | P22: =(D22-O22)/'Test Specimens'!$B$7 -> 0.00090743853 | Q22: =P22*100 -> 0.090743853 | R22: 193.1787 | S22: =ABS(LN(1 - P22)) -> 0.0009078505 | T22: =S22 * 100 -> 0.09078505
A23: 2 | B23: 0.05652 | C23: 1262.4474 | D23: 0.00946 | E23: 204.77655 | F23: 0.0021643 | G23: 0.21643 | H23: 204.33 | I23: 0.0021666 | J23: 0.21666 | N23: =E23*$L$4*'Test Specimens'!$B$7 -> 0.004204872 | O23: =D23-N23 -> 0.005255128 | P23: =(D23-O23)/'Test Specimens'!$B$7 -> 0.00096191832 | Q23: =P23*100 -> 0.096191832 | R23: 204.77655 | S23: =ABS(LN(1 - P23)) -> 0.00096238126 | T23: =S23 * 100 -> 0.096238126
A24: 2.1 | B24: 0.06039 | C24: 1340.4493 | D24: 0.00985 | E24: 217.42892 | F24: 0.0022535 | G24: 0.22535 | H24: 216.94 | I24: 0.002256 | J24: 0.2256 | N24: =E24*$L$4*'Test Specimens'!$B$7 -> 0.0044646752 | O24: =D24-N24 -> 0.0053853248 | P24: =(D24-O24)/'Test Specimens'!$B$7 -> 0.0010213516 | Q24: =P24*100 -> 0.10213516 | R24: 217.42892 | S24: =ABS(LN(1 - P24)) -> 0.0010218736 | T24: =S24 * 100 -> 0.10218736
A25: 2.2 | B25: 0.0642 | C25: 1416.7782 | D25: 0.01051 | E25: 229.80992 | F25: 0.0024045 | G25: 0.24045 | H25: 229.26 | I25: 0.0024074 | J25: 0.24074 | N25: =E25*$L$4*'Test Specimens'!$B$7 -> 0.0047189061 | O25: =D25-N25 -> 0.0057910939 | P25: =(D25-O25)/'Test Specimens'!$B$7 -> 0.0010795102 | Q25: =P25*100 -> 0.10795102 | R25: 229.80992 | S25: =ABS(LN(1 - P25)) -> 0.0010800933 | T25: =S25 * 100 -> 0.10800933
A26: 2.3 | B26: 0.06788 | C26: 1489.9305 | D26: 0.01097 | E26: 241.67567 | F26: 0.0025097 | G26: 0.25097 | H26: 241.07 | I26: 0.0025129 | J26: 0.25129 | N26: =E26*$L$4*'Test Specimens'!$B$7 -> 0.0049625568 | O26: =D26-N26 -> 0.0060074432 | P26: =(D26-O26)/'Test Specimens'!$B$7 -> 0.0011352484 | Q26: =P26*100 -> 0.11352484 | R26: 241.67567 | S26: =ABS(LN(1 - P26)) -> 0.0011358933 | T26: =S26 * 100 -> 0.11358933
... A62: 5.9 | B62: 0.17849 | C62: 3827.7747 | D62: 0.02692 | E62: 620.888 | F62: 0.0061588 | G62: 0.61588 | H62: 617.06 | I62: 0.0061778 | J62: 0.61778 | N62: =E62*$L$4*'Test Specimens'!$B$7 -> 0.012749285 | O62: =D62-N62 -> 0.014170715 | P62: =(D62-O62)/'Test Specimens'!$B$7 -> 0.0029165622 | Q62: =P62*100 -> 0.29165622 | R62: 620.888 | S62: =ABS(LN(1 - P62)) -> 0.0029208236 | T62: =S62 * 100 -> 0.29208236
A63: 6 | B63: 0.18091 | C63: 3882.0249 | D63: 0.02751 | E63: 629.68774 | F63: 0.0062938 | G63: 0.62938 | H63: 625.72 | I63: 0.0063136 | J63: 0.63136 | N63: =E63*$L$4*'Test Specimens'!$B$7 -> 0.012929978 | O63: =C63*$L$10+$M$10 -> 0.014307283 | P63: =(D63-O63)/'Test Specimens'!$B$7 -> 0.0030202906 | Q63: =P63*100 -> 0.30202906 | R63: 629.68774 | S63: =ABS(LN(1 - P63)) -> 0.0030248609 | T63: =S63 * 100 -> 0.30248609
A64: 6.1 | B64: 0.18331 | C64: 3937.7529 | D64: 0.02794 | E64: 638.72717 | F64: 0.0063921 | G64: 0.63921 | H64: 634.64 | I64: 0.0064126 | J64: 0.64126 | N64: =E64*$L$4*'Test Specimens'!$B$7 -> 0.013115594 | O64: =C64*$L$10+$M$10 -> 0.014496811 | P64: =(D64-O64)/'Test Specimens'!$B$7 -> 0.0030753017 | Q64: =P64*100 -> 0.30753017 | R64: 638.72717 | S64: =ABS(LN(1 - P64)) -> 0.0030800402 | T64: =S64 * 100 -> 0.30800402
A65: 6.2 | B65: 0.18558 | C65: 3989.8398 | D65: 0.02856 | E65: 647.17596 | F65: 0.006534 | G65: 0.6534 | H65: 642.95 | I65: 0.0065554 | J65: 0.65554 | N65: =E65*$L$4*'Test Specimens'!$B$7 -> 0.013289081 | O65: =C65*$L$10+$M$10 -> 0.014673955 | P65: =(D65-O65)/'Test Specimens'!$B$7 -> 0.0031766106 | Q65: =P65*100 -> 0.31766106 | R65: 647.17596 | S65: =ABS(LN(1 - P65)) -> 0.0031816667 | T65: =S65 * 100 -> 0.31816667
A66: 6.3 | B66: 0.18769 | C66: 4039.9605 | D66: 0.02885 | E66: 655.30585 | F66: 0.0066003 | G66: 0.66003 | H66: 650.98 | I66: 0.0066222 | J66: 0.66222 | N66: =E66*$L$4*'Test Specimens'!$B$7 -> 0.013456019 | O66: =C66*$L$10+$M$10 -> 0.014844412 | P66: =(D66-O66)/'Test Specimens'!$B$7 -> 0.0032039575 | Q66: =P66*100 -> 0.32039575 | R66: 655.30585 | S66: =ABS(LN(1 - P66)) -> 0.0032091012 | T66: =S66 * 100 -> 0.32091012
A67: 6.4 | B67: 0.18984 | C67: 4089.6238 | D67: 0.02923 | E67: 663.36151 | F67: 0.0066873 | G67: 0.66873 | H67: 658.93 | I67: 0.0067097 | J67: 0.67097 | N67: =E67*$L$4*'Test Specimens'!$B$7 -> 0.013621434 | O67: =C67*$L$10+$M$10 -> 0.015013314 | P67: =(D67-O67)/'Test Specimens'!$B$7 -> 0.0032522489 | Q67: =P67*100 -> 0.32522489 | R67: 663.36151 | S67: =ABS(LN(1 - P67)) -> 0.003257549 | T67: =S67 * 100 -> 0.3257549
A68: 6.5 | B68: 0.19191 | C68: 4140.1435 | D68: 0.02962 | E68: 671.55615 | F68: 0.0067765 | G68: 0.67765 | H68: 667.01 | I68: 0.0067995 | J68: 0.67995 | N68: =E68*$L$4*'Test Specimens'!$B$7 -> 0.013789702 | O68: =C68*$L$10+$M$10 -> 0.015185129 | P68: =(D68-O68)/'Test Specimens'!$B$7 -> 0.0033021616 | Q68: =P68*100 -> 0.33021616 | R68: 671.55615 | S68: =ABS(LN(1 - P68)) -> 0.0033076257 | T68: =S68 * 100 -> 0.33076257
A69: 6.6 | B69: 0.19389 | C69: 4183.7583 | D69: 0.0303 | E69: 678.63068 | F69: 0.006932 | G69: 0.6932 | H69: 673.93 | I69: 0.0069562 | J69: 0.69562 | N69: =E69*$L$4*'Test Specimens'!$B$7 -> 0.01393497 | O69: =C69*$L$10+$M$10 -> 0.01533346 | P69: =(D69-O69)/'Test Specimens'!$B$7 -> 0.0034237876 | Q69: =P69*100 -> 0.34237876 | R69: 678.63068 | S69: =ABS(LN(1 - P69)) -> 0.0034296622 | T69: =S69 * 100 -> 0.34296622
A70: 6.7 | B70: 0.19559 | C70: 4220.1235 | D70: 0.03061 | E70: 684.52936 | F70: 0.007003 | G70: 0.7003 | H70: 679.74 | I70: 0.0070276 | J70: 0.70276 | N70: =E70*$L$4*'Test Specimens'!$B$7 -> 0.014056094 | O70: =C70*$L$10+$M$10 -> 0.015457136 | P70: =(D70-O70)/'Test Specimens'!$B$7 -> 0.0034664116 | Q70: =P70*100 -> 0.34664116 | R70: 684.52936 | S70: =ABS(LN(1 - P70)) -> 0.0034724335 | T70: =S70 * 100 -> 0.34724335
A71: 6.8 | B71: 0.19735 | C71: 4260.8643 | D71: 0.03116 | E71: 691.13776 | F71: 0.0071288 | G71: 0.71288 | H71: 686.21 | I71: 0.0071543 | J71: 0.71543 | N71: =E71*$L$4*'Test Specimens'!$B$7 -> 0.01419179 | O71: =C71*$L$10+$M$10 -> 0.015595693 | P71: =(D71-O71)/'Test Specimens'!$B$7 -> 0.0035605345 | Q71: =P71*100 -> 0.35605345 | R71: 691.13776 | S71: =ABS(LN(1 - P71)) -> 0.0035668883 | T71: =S71 * 100 -> 0.35668883
A72: 6.9 | B72: 0.19897 | C72: 4293.5718 | D72: 0.03154 | E72: 696.44312 | F72: 0.0072157 | G72: 0.72157 | H72: 691.42 | I72: 0.0072419 | J72: 0.72419 | N72: =E72*$L$4*'Test Specimens'!$B$7 -> 0.01430073 | O72: =C72*$L$10+$M$10 -> 0.015706929 | P72: =(D72-O72)/'Test Specimens'!$B$7 -> 0.0036220177 | Q72: =P72*100 -> 0.36220177 | R72: 696.44312 | S72: =ABS(LN(1 - P72)) -> 0.003628593 | T72: =S72 * 100 -> 0.3628593
A73: 7 | B73: 0.20047 | C73: 4324.2622 | D73: 0.03217 | E73: 701.42126 | F73: 0.0073599 | G73: 0.73599 | H73: 696.26 | I73: 0.0073871 | J73: 0.73871 | N73: =E73*$L$4*'Test Specimens'!$B$7 -> 0.014402951 | O73: =C73*$L$10+$M$10 -> 0.015811306 | P73: =(D73-O73)/'Test Specimens'!$B$7 -> 0.0037422608 | Q73: =P73*100 -> 0.37422608 | R73: 701.42126 | S73: =ABS(LN(1 - P73)) -> 0.0037492806 | T73: =S73 * 100 -> 0.37492806
A74: 7.1 | B74: 0.2018 | C74: 4349.3403 | D74: 0.03247 | E74: 705.48907 | F74: 0.0074285 | G74: 0.74285 | H74: 700.25 | I74: 0.0074562 | J74: 0.74562 | N74: =E74*$L$4*'Test Specimens'!$B$7 -> 0.014486479 | O74: =C74*$L$10+$M$10 -> 0.015896595 | P74: =(D74-O74)/'Test Specimens'!$B$7 -> 0.0037913786 | Q74: =P74*100 -> 0.37913786 | R74: 705.48907 | S74: =ABS(LN(1 - P74)) -> 0.0037985841 | T74: =S74 * 100 -> 0.37985841
... A139: 13.6 | B139: 0.24558 | C139: 4814.7456 | D139: 0.05922 | E139: 780.98065 | F139: 0.013548 | G139: 1.3548 | H139: 770.4 | I139: 0.013641 | J139: 1.3641 | N139: =E139*$L$4*'Test Specimens'!$B$7 -> 0.01603662 | O139: =C139*$L$10+$M$10 -> 0.017479411 | P139: =(D139-O139)/'Test Specimens'!$B$7 -> 0.0095486943 | Q139: =P139*100 -> 0.95486943 | R139: 780.98065 | S139: =ABS(LN(1 - P139)) -> 0.0095945754 | T139: =S139 * 100 -> 0.95945754
...
